2025-10-30 10:18:18,905: -: log: INFO: 172.18.0.1 [30/Oct/2025:10:18:18 +0000] "GET /health HTTP/1.1" 200 174 "-" "Mozilla/5.0 (Windows NT 10.0; Win64; x64) AppleWebKit/537.36 (KHTML, like Gecko) Chrome/138.0.0.0 YaBrowser/25.8.0.0 Safari/537.36"
2025-10-30 10:18:28,425: -: log: INFO: 172.18.0.1 [30/Oct/2025:10:18:28 +0000] "POST /images HTTP/1.1" 401 261 "-" "PostmanRuntime/7.46.0"
2025-10-30 10:19:20,642: /images: upload_image: INFO: upload started
2025-10-30 10:19:20,725: /images: upload_image: INFO: upload finished: width=600 height=600 quality=80 size=23391 source=JPEG
2025-10-30 10:19:20,726: -: log: INFO: 172.18.0.1 [30/Oct/2025:10:19:20 +0000] "POST /images HTTP/1.1" 201 377 "-" "PostmanRuntime/7.46.0"
2025-10-30 10:38:25,239: /logs: error_middleware: ERROR: Unhandled error
Traceback (most recent call last):
  File "/app/app/errors.py", line 13, in error_middleware
    return await handler(request)
  File "/app/app/routes.py", line 185, in read_logs
    lines = _tail(log_path, limit)
  File "/app/app/routes.py", line 199, in _tail
    f.seek(seek, os.SEEK_END)
OSError: [Errno 22] Invalid argument
2025-10-30 10:38:25,240: -: log: INFO: 172.18.0.1 [30/Oct/2025:10:38:25 +0000] "GET /logs?limit=200 HTTP/1.1" 500 212 "-" "PostmanRuntime/7.46.0"
2025-10-30 10:38:38,360: /logs: error_middleware: ERROR: Unhandled error
Traceback (most recent call last):
  File "/app/app/errors.py", line 13, in error_middleware
    return await handler(request)
  File "/app/app/routes.py", line 185, in read_logs
    lines = _tail(log_path, limit)
  File "/app/app/routes.py", line 199, in _tail
    f.seek(seek, os.SEEK_END)
OSError: [Errno 22] Invalid argument
2025-10-30 10:38:38,361: -: log: INFO: 172.18.0.1 [30/Oct/2025:10:38:38 +0000] "GET /logs HTTP/1.1" 500 212 "-" "PostmanRuntime/7.46.0"
2025-10-30 10:40:49,476: /logs: error_middleware: ERROR: Unhandled error
Traceback (most recent call last):
  File "/app/app/errors.py", line 13, in error_middleware
    return await handler(request)
  File "/app/app/routes.py", line 190, in read_logs
    return web.Response(text="".join(lines), content_type="text/plain; charset=utf-8")
  File "/usr/local/lib/python3.9/site-packages/aiohttp/web_response.py", line 650, in __init__
    raise ValueError("charset must not be in content_type argument")
ValueError: charset must not be in content_type argument
2025-10-30 10:40:49,477: -: log: INFO: 172.18.0.1 [30/Oct/2025:10:40:49 +0000] "GET /logs HTTP/1.1" 500 212 "-" "PostmanRuntime/7.46.0"
